[

{"@id": "http://docs.oasis-open.org/tac/ns/stix-cve#CVE-2020-35917", "@type": ["http://www.w3.org/2002/07/owl#NamedIndividual", "http://docs.oasis-open.org/cti/ns/stix#Vulnerability"], "http://docs.oasis-open.org/cti/ns/stix/core#description": [{"@value": "An issue was discovered in the pyo3 crate before 0.12.4 for Rust. There is a reference-counting error and use-after-free in From<Py<T>>."}], "http://docs.oasis-open.org/cti/ns/stix/core#modified": [{"@value": "2021-03-13T20:12:21.795225Z"}], "http://docs.oasis-open.org/cti/ns/stix/core#created": [{"@value": "2021-03-13T20:12:21.795225Z"}], "http://docs.oasis-open.org/cti/ns/stix/core#spec_version": [{"@value": "2.1"}], "http://docs.oasis-open.org/cti/ns/stix/core#id": [{"@value": "vulnerability--21554d81-468c-474d-bbc5-e805b679bec8"}], "http://docs.oasis-open.org/cti/ns/stix/core#name": [{"@value": "CVE-2020-35917"}], "http://docs.oasis-open.org/cti/ns/stix/core#created_by_ref": [{"@id": "http://docs.oasis-open.org/tac/ns/stix-cve#identity--8ce3f695-d5a4-4dc8-9e93-a65af453a31a"}], "http://docs.oasis-open.org/cti/ns/stix/marking#object_marking_refs": [{"@id": "http://docs.oasis-open.org/tac/ns/stix-cve#marking-definition--62fd3f9b-15f3-4ebc-802c-91fce9536bcf"}]}

]