[

{"@id": "http://docs.oasis-open.org/tac/ns/stix-cve#CVE-2020-24584", "@type": ["http://www.w3.org/2002/07/owl#NamedIndividual", "http://docs.oasis-open.org/cti/ns/stix#Vulnerability"], "http://docs.oasis-open.org/cti/ns/stix/core#description": [{"@value": "An issue was discovered in Django 2.2 before 2.2.16, 3.0 before 3.0.10, and 3.1 before 3.1.1 (when Python 3.7+ is used). The intermediate-level directories of the filesystem cache had the system's standard umask rather than 0o077."}], "http://docs.oasis-open.org/cti/ns/stix/core#modified": [{"@value": "2021-03-13T20:12:31.096415Z"}], "http://docs.oasis-open.org/cti/ns/stix/core#created": [{"@value": "2021-03-13T20:12:31.096415Z"}], "http://docs.oasis-open.org/cti/ns/stix/core#spec_version": [{"@value": "2.1"}], "http://docs.oasis-open.org/cti/ns/stix/core#id": [{"@value": "vulnerability--a5d75f48-b04f-455b-bb72-dc7b8633d5de"}], "http://docs.oasis-open.org/cti/ns/stix/core#name": [{"@value": "CVE-2020-24584"}], "http://docs.oasis-open.org/cti/ns/stix/core#created_by_ref": [{"@id": "http://docs.oasis-open.org/tac/ns/stix-cve#identity--8ce3f695-d5a4-4dc8-9e93-a65af453a31a"}], "http://docs.oasis-open.org/cti/ns/stix/marking#object_marking_refs": [{"@id": "http://docs.oasis-open.org/tac/ns/stix-cve#marking-definition--62fd3f9b-15f3-4ebc-802c-91fce9536bcf"}]}

]